2022-07-13 23:00:09,904 INFO    MainThread:816 [wandb_setup.py:_flush():76] Configure stats pid to 816
2022-07-13 23:00:09,904 INFO    MainThread:816 [wandb_setup.py:_flush():76] Loading settings from C:\Users\Yy\.config\wandb\settings
2022-07-13 23:00:09,905 INFO    MainThread:816 [wandb_setup.py:_flush():76] Loading settings from D:\my_code_2\my_code\tutorial-MixMatch-master\wandb\settings
2022-07-13 23:00:09,905 INFO    MainThread:816 [wandb_setup.py:_flush():76] Loading settings from environment variables: {}
2022-07-13 23:00:09,905 INFO    MainThread:816 [wandb_setup.py:_flush():76] Inferring run settings from compute environment: {'program': '<python with no main file>'}
2022-07-13 23:00:09,906 INFO    MainThread:816 [wandb_init.py:_log_setup():461] Logging user logs to D:\my_code_2\my_code\tutorial-MixMatch-master\wandb\run-20220713_230009-23b6j2id\logs\debug.log
2022-07-13 23:00:09,906 INFO    MainThread:816 [wandb_init.py:_log_setup():462] Logging internal logs to D:\my_code_2\my_code\tutorial-MixMatch-master\wandb\run-20220713_230009-23b6j2id\logs\debug-internal.log
2022-07-13 23:00:09,907 INFO    MainThread:816 [wandb_init.py:_jupyter_setup():411] configuring jupyter hooks <wandb.sdk.wandb_init._WandbInit object at 0x0000021CC0BAD370>
2022-07-13 23:00:09,908 INFO    MainThread:816 [wandb_init.py:init():495] calling init triggers
2022-07-13 23:00:09,908 INFO    MainThread:816 [wandb_init.py:init():498] wandb.init called with sweep_config: {}
config: {}
2022-07-13 23:00:09,908 INFO    MainThread:816 [wandb_init.py:init():548] starting backend
2022-07-13 23:00:09,908 INFO    MainThread:816 [backend.py:_multiprocessing_setup():97] multiprocessing start_methods=spawn, using: spawn
2022-07-13 23:00:09,917 INFO    MainThread:816 [backend.py:ensure_launched():217] starting backend process...
2022-07-13 23:00:09,985 INFO    MainThread:816 [backend.py:ensure_launched():222] started backend process with pid: 10828
2022-07-13 23:00:09,985 INFO    MainThread:816 [wandb_init.py:init():558] backend started and connected
2022-07-13 23:00:09,997 INFO    MainThread:816 [wandb_run.py:_label_probe_notebook():1084] probe notebook
2022-07-13 23:00:10,001 INFO    MainThread:816 [wandb_init.py:init():634] updated telemetry
2022-07-13 23:00:10,021 INFO    MainThread:816 [wandb_init.py:init():665] communicating run to backend with 30 second timeout
2022-07-13 23:00:14,666 ERROR   Thread-12 :816 [retry.py:__call__():132] Retry attempt failed:
Traceback (most recent call last):
  File "c:\users\yy\miniconda3\lib\site-packages\urllib3\connection.py", line 159, in _new_conn
    conn = connection.create_connection(
  File "c:\users\yy\miniconda3\lib\site-packages\urllib3\util\connection.py", line 84, in create_connection
    raise err
  File "c:\users\yy\miniconda3\lib\site-packages\urllib3\util\connection.py", line 74, in create_connection
    sock.connect(sa)
ConnectionRefusedError: [WinError 10061] 由于目标计算机积极拒绝，无法连接。

During handling of the above exception, another exception occurred:

Traceback (most recent call last):
  File "c:\users\yy\miniconda3\lib\site-packages\urllib3\connectionpool.py", line 667, in urlopen
    self._prepare_proxy(conn)
  File "c:\users\yy\miniconda3\lib\site-packages\urllib3\connectionpool.py", line 932, in _prepare_proxy
    conn.connect()
  File "c:\users\yy\miniconda3\lib\site-packages\urllib3\connection.py", line 309, in connect
    conn = self._new_conn()
  File "c:\users\yy\miniconda3\lib\site-packages\urllib3\connection.py", line 171, in _new_conn
    raise NewConnectionError(
urllib3.exceptions.NewConnectionError: <urllib3.connection.HTTPSConnection object at 0x0000021CC4D95D90>: Failed to establish a new connection: [WinError 10061] 由于目标计算机积极拒绝，无法连接。

During handling of the above exception, another exception occurred:

Traceback (most recent call last):
  File "c:\users\yy\miniconda3\lib\site-packages\requests\adapters.py", line 439, in send
    resp = conn.urlopen(
  File "c:\users\yy\miniconda3\lib\site-packages\urllib3\connectionpool.py", line 726, in urlopen
    retries = retries.increment(
  File "c:\users\yy\miniconda3\lib\site-packages\urllib3\util\retry.py", line 446, in increment
    raise MaxRetryError(_pool, url, error or ResponseError(cause))
urllib3.exceptions.MaxRetryError: HTTPSConnectionPool(host='api.wandb.ai', port=443): Max retries exceeded with url: /graphql (Caused by ProxyError('Cannot connect to proxy.', NewConnectionError('<urllib3.connection.HTTPSConnection object at 0x0000021CC4D95D90>: Failed to establish a new connection: [WinError 10061] 由于目标计算机积极拒绝，无法连接。')))

During handling of the above exception, another exception occurred:

Traceback (most recent call last):
  File "c:\users\yy\miniconda3\lib\site-packages\wandb\sdk\lib\retry.py", line 108, in __call__
    result = self._call_fn(*args, **kwargs)
  File "c:\users\yy\miniconda3\lib\site-packages\wandb\sdk\internal\internal_api.py", line 158, in execute
    return self.client.execute(*args, **kwargs)
  File "c:\users\yy\miniconda3\lib\site-packages\wandb\vendor\gql-0.2.0\wandb_gql\client.py", line 52, in execute
    result = self._get_result(document, *args, **kwargs)
  File "c:\users\yy\miniconda3\lib\site-packages\wandb\vendor\gql-0.2.0\wandb_gql\client.py", line 60, in _get_result
    return self.transport.execute(document, *args, **kwargs)
  File "c:\users\yy\miniconda3\lib\site-packages\wandb\vendor\gql-0.2.0\wandb_gql\transport\requests.py", line 38, in execute
    request = requests.post(self.url, **post_args)
  File "c:\users\yy\miniconda3\lib\site-packages\requests\api.py", line 119, in post
    return request('post', url, data=data, json=json, **kwargs)
  File "c:\users\yy\miniconda3\lib\site-packages\requests\api.py", line 61, in request
    return session.request(method=method, url=url, **kwargs)
  File "c:\users\yy\miniconda3\lib\site-packages\requests\sessions.py", line 530, in request
    resp = self.send(prep, **send_kwargs)
  File "c:\users\yy\miniconda3\lib\site-packages\requests\sessions.py", line 643, in send
    r = adapter.send(request, **kwargs)
  File "c:\users\yy\miniconda3\lib\site-packages\requests\adapters.py", line 510, in send
    raise ProxyError(e, request=request)
requests.exceptions.ProxyError: HTTPSConnectionPool(host='api.wandb.ai', port=443): Max retries exceeded with url: /graphql (Caused by ProxyError('Cannot connect to proxy.', NewConnectionError('<urllib3.connection.HTTPSConnection object at 0x0000021CC4D95D90>: Failed to establish a new connection: [WinError 10061] 由于目标计算机积极拒绝，无法连接。')))
2022-07-13 23:00:40,034 INFO    MainThread:816 [interface_shared.py:_communicate_run():326] couldn't get run from backend
2022-07-13 23:00:40,034 ERROR   MainThread:816 [wandb_init.py:init():674] backend process timed out
2022-07-13 23:00:40,035 ERROR   MainThread:816 [wandb_init.py:init():685] encountered error: Error communicating with wandb process
try: wandb.init(settings=wandb.Settings(start_method='fork'))
or:  wandb.init(settings=wandb.Settings(start_method='thread'))
For more info see: https://docs.wandb.ai/library/init#init-start-error
2022-07-13 23:02:03,690 INFO    MainThread:816 [wandb_init.py:teardown():302] tearing down wandb.init
