2022-07-13 23:00:11,105 INFO    MainThread:10828 [internal.py:wandb_internal():90] W&B internal server running at pid: 10828, started at: 2022-07-13 23:00:11.104602
2022-07-13 23:00:11,107 INFO    WriterThread:10828 [datastore.py:open_for_write():75] open: D:\my_code_2\my_code\tutorial-MixMatch-master\wandb\run-20220713_230009-23b6j2id\run-23b6j2id.wandb
2022-07-13 23:00:11,114 DEBUG   SenderThread:10828 [sender.py:send():236] send: header
2022-07-13 23:00:11,114 DEBUG   SenderThread:10828 [sender.py:send():236] send: run
2022-07-13 23:00:20,776 ERROR   SenderThread:10828 [retry.py:__call__():132] Retry attempt failed:
Traceback (most recent call last):
  File "c:\users\yy\miniconda3\lib\site-packages\urllib3\connection.py", line 159, in _new_conn
    conn = connection.create_connection(
  File "c:\users\yy\miniconda3\lib\site-packages\urllib3\util\connection.py", line 84, in create_connection
    raise err
  File "c:\users\yy\miniconda3\lib\site-packages\urllib3\util\connection.py", line 74, in create_connection
    sock.connect(sa)
ConnectionRefusedError: [WinError 10061] 由于目标计算机积极拒绝，无法连接。

During handling of the above exception, another exception occurred:

Traceback (most recent call last):
  File "c:\users\yy\miniconda3\lib\site-packages\urllib3\connectionpool.py", line 667, in urlopen
    self._prepare_proxy(conn)
  File "c:\users\yy\miniconda3\lib\site-packages\urllib3\connectionpool.py", line 932, in _prepare_proxy
    conn.connect()
  File "c:\users\yy\miniconda3\lib\site-packages\urllib3\connection.py", line 309, in connect
    conn = self._new_conn()
  File "c:\users\yy\miniconda3\lib\site-packages\urllib3\connection.py", line 171, in _new_conn
    raise NewConnectionError(
urllib3.exceptions.NewConnectionError: <urllib3.connection.HTTPSConnection object at 0x000001D98F3AA9A0>: Failed to establish a new connection: [WinError 10061] 由于目标计算机积极拒绝，无法连接。

During handling of the above exception, another exception occurred:

Traceback (most recent call last):
  File "c:\users\yy\miniconda3\lib\site-packages\requests\adapters.py", line 439, in send
    resp = conn.urlopen(
  File "c:\users\yy\miniconda3\lib\site-packages\urllib3\connectionpool.py", line 726, in urlopen
    retries = retries.increment(
  File "c:\users\yy\miniconda3\lib\site-packages\urllib3\util\retry.py", line 446, in increment
    raise MaxRetryError(_pool, url, error or ResponseError(cause))
urllib3.exceptions.MaxRetryError: HTTPSConnectionPool(host='api.wandb.ai', port=443): Max retries exceeded with url: /graphql (Caused by ProxyError('Cannot connect to proxy.', NewConnectionError('<urllib3.connection.HTTPSConnection object at 0x000001D98F3AA9A0>: Failed to establish a new connection: [WinError 10061] 由于目标计算机积极拒绝，无法连接。')))

During handling of the above exception, another exception occurred:

Traceback (most recent call last):
  File "c:\users\yy\miniconda3\lib\site-packages\wandb\sdk\lib\retry.py", line 108, in __call__
    result = self._call_fn(*args, **kwargs)
  File "c:\users\yy\miniconda3\lib\site-packages\wandb\sdk\internal\internal_api.py", line 158, in execute
    return self.client.execute(*args, **kwargs)
  File "c:\users\yy\miniconda3\lib\site-packages\wandb\vendor\gql-0.2.0\wandb_gql\client.py", line 52, in execute
    result = self._get_result(document, *args, **kwargs)
  File "c:\users\yy\miniconda3\lib\site-packages\wandb\vendor\gql-0.2.0\wandb_gql\client.py", line 60, in _get_result
    return self.transport.execute(document, *args, **kwargs)
  File "c:\users\yy\miniconda3\lib\site-packages\wandb\vendor\gql-0.2.0\wandb_gql\transport\requests.py", line 38, in execute
    request = requests.post(self.url, **post_args)
  File "c:\users\yy\miniconda3\lib\site-packages\requests\api.py", line 119, in post
    return request('post', url, data=data, json=json, **kwargs)
  File "c:\users\yy\miniconda3\lib\site-packages\requests\api.py", line 61, in request
    return session.request(method=method, url=url, **kwargs)
  File "c:\users\yy\miniconda3\lib\site-packages\requests\sessions.py", line 530, in request
    resp = self.send(prep, **send_kwargs)
  File "c:\users\yy\miniconda3\lib\site-packages\requests\sessions.py", line 643, in send
    r = adapter.send(request, **kwargs)
  File "c:\users\yy\miniconda3\lib\site-packages\requests\adapters.py", line 510, in send
    raise ProxyError(e, request=request)
requests.exceptions.ProxyError: HTTPSConnectionPool(host='api.wandb.ai', port=443): Max retries exceeded with url: /graphql (Caused by ProxyError('Cannot connect to proxy.', NewConnectionError('<urllib3.connection.HTTPSConnection object at 0x000001D98F3AA9A0>: Failed to establish a new connection: [WinError 10061] 由于目标计算机积极拒绝，无法连接。')))
2022-07-13 23:00:40,036 DEBUG   HandlerThread:10828 [handler.py:handle_request():140] handle_request: shutdown
2022-07-13 23:00:40,037 INFO    HandlerThread:10828 [handler.py:finish():806] shutting down handler
2022-07-13 23:00:40,301 INFO    WriterThread:10828 [datastore.py:close():279] close: D:\my_code_2\my_code\tutorial-MixMatch-master\wandb\run-20220713_230009-23b6j2id\run-23b6j2id.wandb
2022-07-13 23:01:41,221 INFO    SenderThread:10828 [dir_watcher.py:__init__():216] watching files in: D:\my_code_2\my_code\tutorial-MixMatch-master\wandb\run-20220713_230009-23b6j2id\files
2022-07-13 23:01:41,221 INFO    SenderThread:10828 [sender.py:_start_run_threads():815] run started: 23b6j2id with start time 1657724409
2022-07-13 23:01:41,221 INFO    SenderThread:10828 [sender.py:finish():1114] shutting down sender
2022-07-13 23:01:41,221 INFO    SenderThread:10828 [dir_watcher.py:finish():353] shutting down directory watcher
2022-07-13 23:01:42,234 INFO    SenderThread:10828 [dir_watcher.py:finish():383] scan: D:\my_code_2\my_code\tutorial-MixMatch-master\wandb\run-20220713_230009-23b6j2id\files
2022-07-13 23:01:42,234 INFO    SenderThread:10828 [dir_watcher.py:finish():397] scan save: D:\my_code_2\my_code\tutorial-MixMatch-master\wandb\run-20220713_230009-23b6j2id\files\config.yaml config.yaml
2022-07-13 23:01:42,235 INFO    SenderThread:10828 [file_pusher.py:finish():171] shutting down file pusher
2022-07-13 23:01:42,235 INFO    SenderThread:10828 [file_pusher.py:join():176] waiting for file pusher
2022-07-13 23:01:56,212 ERROR   Thread-13 :10828 [internal_api.py:upload_file():1694] upload_file exception https://storage.googleapis.com/wandb-production.appspot.com/vs74/Expand-ai-problem-2/23b6j2id/config.yaml?Expires=1657810908&GoogleAccessId=wandb-production%40appspot.gserviceaccount.com&Signature=hhS1v9R4Zk1DTN%2F3cl6kSbdfGPOjzmObl3e%2BBNiCaJYovLusNgszCCPTSEDCtLjLAr%2F5AyalJJmVodvVqdRuOBJDsxlGP%2B9fee%2BztMRtWcvGyei5Peb%2Fpb14qe6lHx0ss0EmmcbXG4%2FdJz9vCSN%2FCm1GfrVReUvEhnlvnux%2BF565VVy4Qf4zRX8vfSF%2F0vv7Y2kBHbAFyj1ovL2Ar5hlKCyssMhjd%2F6FLzBR1H1EBUyUtoID7tERlafzsajqqZKnWbyQSnoESzSM0uVeswbpQhiDYAZFB863Sgb9zZLx2IznsDk9Xngj5jrrQgsQb6%2BySlw6uAmmLG10ORqj8HtSNg%3D%3D: HTTPSConnectionPool(host='storage.googleapis.com', port=443): Max retries exceeded with url: /wandb-production.appspot.com/vs74/Expand-ai-problem-2/23b6j2id/config.yaml?Expires=1657810908&GoogleAccessId=wandb-production%40appspot.gserviceaccount.com&Signature=hhS1v9R4Zk1DTN%2F3cl6kSbdfGPOjzmObl3e%2BBNiCaJYovLusNgszCCPTSEDCtLjLAr%2F5AyalJJmVodvVqdRuOBJDsxlGP%2B9fee%2BztMRtWcvGyei5Peb%2Fpb14qe6lHx0ss0EmmcbXG4%2FdJz9vCSN%2FCm1GfrVReUvEhnlvnux%2BF565VVy4Qf4zRX8vfSF%2F0vv7Y2kBHbAFyj1ovL2Ar5hlKCyssMhjd%2F6FLzBR1H1EBUyUtoID7tERlafzsajqqZKnWbyQSnoESzSM0uVeswbpQhiDYAZFB863Sgb9zZLx2IznsDk9Xngj5jrrQgsQb6%2BySlw6uAmmLG10ORqj8HtSNg%3D%3D (Caused by ProxyError('Cannot connect to proxy.', ConnectionResetError(10054, '远程主机强迫关闭了一个现有的连接。', None, 10054, None)))
2022-07-13 23:01:56,212 ERROR   Thread-13 :10828 [internal_api.py:upload_file():1696] upload_file request headers: {'User-Agent': 'python-requests/2.24.0', 'Accept-Encoding': 'gzip, deflate', 'Accept': '*/*', 'Connection': 'keep-alive', 'Content-Length': '341'}
2022-07-13 23:01:56,213 ERROR   Thread-13 :10828 [internal_api.py:upload_file():1698] upload_file response body: 
2022-07-13 23:01:59,212 INFO    Thread-13 :10828 [upload_job.py:push():138] Uploaded file D:\my_code_2\my_code\tutorial-MixMatch-master\wandb\run-20220713_230009-23b6j2id\files\config.yaml
2022-07-13 23:02:03,548 INFO    MainThread:10828 [internal.py:handle_exit():80] Internal process exited
