2022-08-03 17:58:51,545 INFO    MainThread:19392 [internal.py:wandb_internal():90] W&B internal server running at pid: 19392, started at: 2022-08-03 17:58:51.545017
2022-08-03 17:58:51,546 INFO    WriterThread:19392 [datastore.py:open_for_write():75] open: D:\my_code_2\my_code\tutorial-MixMatch-master\wandb\run-20220803_175850-1lxek62u\run-1lxek62u.wandb
2022-08-03 17:58:51,556 DEBUG   SenderThread:19392 [sender.py:send():236] send: header
2022-08-03 17:58:51,556 DEBUG   SenderThread:19392 [sender.py:send():236] send: run
2022-08-03 17:59:00,819 ERROR   SenderThread:19392 [retry.py:__call__():132] Retry attempt failed:
Traceback (most recent call last):
  File "C:\Users\Yy\miniconda3\lib\site-packages\urllib3\connection.py", line 159, in _new_conn
    conn = connection.create_connection(
  File "C:\Users\Yy\miniconda3\lib\site-packages\urllib3\util\connection.py", line 84, in create_connection
    raise err
  File "C:\Users\Yy\miniconda3\lib\site-packages\urllib3\util\connection.py", line 74, in create_connection
    sock.connect(sa)
ConnectionRefusedError: [WinError 10061] 由于目标计算机积极拒绝，无法连接。

During handling of the above exception, another exception occurred:

Traceback (most recent call last):
  File "C:\Users\Yy\miniconda3\lib\site-packages\urllib3\connectionpool.py", line 667, in urlopen
    self._prepare_proxy(conn)
  File "C:\Users\Yy\miniconda3\lib\site-packages\urllib3\connectionpool.py", line 932, in _prepare_proxy
    conn.connect()
  File "C:\Users\Yy\miniconda3\lib\site-packages\urllib3\connection.py", line 309, in connect
    conn = self._new_conn()
  File "C:\Users\Yy\miniconda3\lib\site-packages\urllib3\connection.py", line 171, in _new_conn
    raise NewConnectionError(
urllib3.exceptions.NewConnectionError: <urllib3.connection.HTTPSConnection object at 0x000002504A15C970>: Failed to establish a new connection: [WinError 10061] 由于目标计算机积极拒绝，无法连接。

During handling of the above exception, another exception occurred:

Traceback (most recent call last):
  File "C:\Users\Yy\miniconda3\lib\site-packages\requests\adapters.py", line 439, in send
    resp = conn.urlopen(
  File "C:\Users\Yy\miniconda3\lib\site-packages\urllib3\connectionpool.py", line 726, in urlopen
    retries = retries.increment(
  File "C:\Users\Yy\miniconda3\lib\site-packages\urllib3\util\retry.py", line 446, in increment
    raise MaxRetryError(_pool, url, error or ResponseError(cause))
urllib3.exceptions.MaxRetryError: HTTPSConnectionPool(host='api.wandb.ai', port=443): Max retries exceeded with url: /graphql (Caused by ProxyError('Cannot connect to proxy.', NewConnectionError('<urllib3.connection.HTTPSConnection object at 0x000002504A15C970>: Failed to establish a new connection: [WinError 10061] 由于目标计算机积极拒绝，无法连接。')))

During handling of the above exception, another exception occurred:

Traceback (most recent call last):
  File "C:\Users\Yy\miniconda3\lib\site-packages\wandb\sdk\lib\retry.py", line 108, in __call__
    result = self._call_fn(*args, **kwargs)
  File "C:\Users\Yy\miniconda3\lib\site-packages\wandb\sdk\internal\internal_api.py", line 158, in execute
    return self.client.execute(*args, **kwargs)
  File "C:\Users\Yy\miniconda3\lib\site-packages\wandb\vendor\gql-0.2.0\wandb_gql\client.py", line 52, in execute
    result = self._get_result(document, *args, **kwargs)
  File "C:\Users\Yy\miniconda3\lib\site-packages\wandb\vendor\gql-0.2.0\wandb_gql\client.py", line 60, in _get_result
    return self.transport.execute(document, *args, **kwargs)
  File "C:\Users\Yy\miniconda3\lib\site-packages\wandb\vendor\gql-0.2.0\wandb_gql\transport\requests.py", line 38, in execute
    request = requests.post(self.url, **post_args)
  File "C:\Users\Yy\miniconda3\lib\site-packages\requests\api.py", line 119, in post
    return request('post', url, data=data, json=json, **kwargs)
  File "C:\Users\Yy\miniconda3\lib\site-packages\requests\api.py", line 61, in request
    return session.request(method=method, url=url, **kwargs)
  File "C:\Users\Yy\miniconda3\lib\site-packages\requests\sessions.py", line 530, in request
    resp = self.send(prep, **send_kwargs)
  File "C:\Users\Yy\miniconda3\lib\site-packages\requests\sessions.py", line 643, in send
    r = adapter.send(request, **kwargs)
  File "C:\Users\Yy\miniconda3\lib\site-packages\requests\adapters.py", line 510, in send
    raise ProxyError(e, request=request)
requests.exceptions.ProxyError: HTTPSConnectionPool(host='api.wandb.ai', port=443): Max retries exceeded with url: /graphql (Caused by ProxyError('Cannot connect to proxy.', NewConnectionError('<urllib3.connection.HTTPSConnection object at 0x000002504A15C970>: Failed to establish a new connection: [WinError 10061] 由于目标计算机积极拒绝，无法连接。')))
2022-08-03 17:59:20,227 DEBUG   HandlerThread:19392 [handler.py:handle_request():140] handle_request: shutdown
2022-08-03 17:59:20,228 INFO    HandlerThread:19392 [handler.py:finish():806] shutting down handler
2022-08-03 17:59:20,862 INFO    WriterThread:19392 [datastore.py:close():279] close: D:\my_code_2\my_code\tutorial-MixMatch-master\wandb\run-20220803_175850-1lxek62u\run-1lxek62u.wandb
2022-08-03 18:00:15,553 INFO    SenderThread:19392 [dir_watcher.py:__init__():216] watching files in: D:\my_code_2\my_code\tutorial-MixMatch-master\wandb\run-20220803_175850-1lxek62u\files
2022-08-03 18:00:15,553 INFO    SenderThread:19392 [sender.py:_start_run_threads():815] run started: 1lxek62u with start time 1659520730
2022-08-03 18:00:15,554 INFO    SenderThread:19392 [sender.py:finish():1114] shutting down sender
2022-08-03 18:00:15,554 INFO    SenderThread:19392 [dir_watcher.py:finish():353] shutting down directory watcher
2022-08-03 18:00:16,560 INFO    SenderThread:19392 [dir_watcher.py:finish():383] scan: D:\my_code_2\my_code\tutorial-MixMatch-master\wandb\run-20220803_175850-1lxek62u\files
2022-08-03 18:00:16,561 INFO    SenderThread:19392 [dir_watcher.py:finish():397] scan save: D:\my_code_2\my_code\tutorial-MixMatch-master\wandb\run-20220803_175850-1lxek62u\files\config.yaml config.yaml
2022-08-03 18:00:16,562 INFO    SenderThread:19392 [file_pusher.py:finish():171] shutting down file pusher
2022-08-03 18:00:16,562 INFO    SenderThread:19392 [file_pusher.py:join():176] waiting for file pusher
2022-08-03 18:00:17,445 ERROR   Thread-13 :19392 [internal_api.py:upload_file():1694] upload_file exception https://storage.googleapis.com/wandb-production.appspot.com/vs74/Expand-ai-problem-2/1lxek62u/config.yaml?Expires=1659607217&GoogleAccessId=wandb-production%40appspot.gserviceaccount.com&Signature=oZNy4C5DxjsGSVL7GasaB6oFLRAC2%2BGY3GCz1CKkolsDJKyZfJqgpp9PYuSQXUkYAd0N7Cyp57NEwhDsOG%2BofrB%2FtC7KilHBUMKjEcl%2B56sEDGlAnBblKsLuPPffKT6AZDWZjuWwEKmxVsaap47tn0%2F1zj%2B6Nk8qlOoWTo0L1u%2Fb%2FbtrSQ1nFrP1QRqLHugghitcMz3JHDbeH7s6abnSE1If2DIITEQjn0fL46dzmyNRC7me%2BhPYUp4qUwxyMzD4N0V%2BnBtY9vVYazOqjHn%2BPfhuZ2SjZJH7Yu%2FBxavg%2FafhhDv0cJDzukYD5AgPjpCF4pzI4a47cfJGUj0AXSbANQ%3D%3D: HTTPSConnectionPool(host='storage.googleapis.com', port=443): Max retries exceeded with url: /wandb-production.appspot.com/vs74/Expand-ai-problem-2/1lxek62u/config.yaml?Expires=1659607217&GoogleAccessId=wandb-production%40appspot.gserviceaccount.com&Signature=oZNy4C5DxjsGSVL7GasaB6oFLRAC2%2BGY3GCz1CKkolsDJKyZfJqgpp9PYuSQXUkYAd0N7Cyp57NEwhDsOG%2BofrB%2FtC7KilHBUMKjEcl%2B56sEDGlAnBblKsLuPPffKT6AZDWZjuWwEKmxVsaap47tn0%2F1zj%2B6Nk8qlOoWTo0L1u%2Fb%2FbtrSQ1nFrP1QRqLHugghitcMz3JHDbeH7s6abnSE1If2DIITEQjn0fL46dzmyNRC7me%2BhPYUp4qUwxyMzD4N0V%2BnBtY9vVYazOqjHn%2BPfhuZ2SjZJH7Yu%2FBxavg%2FafhhDv0cJDzukYD5AgPjpCF4pzI4a47cfJGUj0AXSbANQ%3D%3D (Caused by ProxyError('Cannot connect to proxy.', OSError(0, 'Error')))
2022-08-03 18:00:17,446 ERROR   Thread-13 :19392 [internal_api.py:upload_file():1696] upload_file request headers: {'User-Agent': 'python-requests/2.24.0', 'Accept-Encoding': 'gzip, deflate', 'Accept': '*/*', 'Connection': 'keep-alive', 'Content-Length': '331'}
2022-08-03 18:00:17,446 ERROR   Thread-13 :19392 [internal_api.py:upload_file():1698] upload_file response body: 
2022-08-03 18:00:19,325 INFO    Thread-13 :19392 [upload_job.py:push():138] Uploaded file D:\my_code_2\my_code\tutorial-MixMatch-master\wandb\run-20220803_175850-1lxek62u\files\config.yaml
2022-08-03 18:00:20,162 INFO    MainThread:19392 [internal.py:handle_exit():80] Internal process exited
